Workbook

Sheet Cover sheet
A1: Mid-Year Population Estimates, England and Wales, June 2025
A2: This spreadsheet contains a selection of the data tables published alongside the Office for National Statistics' Mid-Year Population Estimates June 2025.
A3: Mid-Year Population Estimates, England and Wales, June 2025
A4: Publication dates
A5: The data tables in this spreadsheet were originally published at 9.30am 29 July 2026.
A6: The next publication is scheduled for summer 2027.
A7: Dataset identifier codes
A8: The country and local authority codes are 9 digits long and are used as geography identifiers.
A9: Comparing mid-year population estimates changes
A10: When comparing mid-year population datasets please be aware that while they are broadly comparable, different data sources and methods are used to create the estimates for England and Wales, Scotland, and for Northern Ireland. Differences can also occur between years. Please see the Quality and Methodology Guide (QMG) report linked below for more information.
A11: Historic publication dates for mid-year population estimates statistics
A12: The annual mid-year population estimates statistics roll forward the population statistics produced from decennial Censuses. The series of current population estimates is available from the tables page where this file is published.
... A31: Date published: 29 July 2026

Sheet Contents
A1: Table of contents
A2: Worksheet number/name | B2: Worksheet title
A3: Cover sheet | B3: Cover sheet
A4: Notes | B4: Notes
A5: Geography guide | B5: Geography guide
A6: Related publications | B6: Provides links to further population statistics and related publications
A7: MYE0 | B7: Population estimates and Research-based measures of statistical uncertainty: Summary for England and Wales, mid-2021 to mid-2025
A8: MYE1 | B8: Population estimates: Summary for England and Wales, mid-2025
A9: MYE2 - Persons | B9: Persons by single year of age and sex for local authorities in England and Wales, mid-2025
A10: MYE2 - Females | B10: Females by single year of age and sex for local authorities in England and Wales, mid-2025
A11: MYE2 - Males | B11: Males by single year of age and sex for local authorities in England and Wales, mid-2025
A12: MYE3 | B12: Components of population change for local authorities in England and Wales, mid-2025
A13: MYE4 | B13: Population estimates: Summary for England and Wales, mid-2011 to mid-2025
... A16: MYE7 | B16: Summary revisions to mid-2022 to mid-2024 estimates for England & Wales

Sheet Notes
A1: Notes related to the data in this spreadsheet
A2: Issues affecting all tables | B2: Note text | C2: Related Links
A3: 1 | B3: Accuracy of estimates and rounding: estimates are presented unrounded. Unrounded estimates are published to enable and encourage further calculations and analysis. However, the estimates should not be taken to be accurate to the level of detail provided. Confidence Intervals for population estimates and the local authority, county, region and country level are provided in table MYE0 in this workbook. More information on the accuracy of the estimates is available in the Quality and Methodology Guide (QMG). | C3: Population estimates for England and Wales QMG
A4: 2 | B4: Small counts: the estimates are produced using a variety of data sources and statistical models, including some statistical disclosure control methods, and small estimates should not be taken to refer to particular individuals. | C4: No Link
A5: 3 | B5: Usual residence definitions: the estimated resident population of an area includes all those people who usually live there, regardless of nationality. Arriving international migrants are included in the usually resident population if they remain in the UK for at least a year. Emigrants are excluded if they remain outside the UK for at least a year. This is consistent with the United Nations definition of a long-term migrant. Armed forces stationed outside of the UK are excluded. Students are taken to be usually resident at their term time address. | C5: No Link
A6: 4 | B6: Geography: where subnational level data are presented, the population estimates reflect boundaries in place as of April 2024. The term "local authority district" refers to geographical areas in the tables which are below regions and which are not counties or metropolitan counties. In England these include unitary authorities, metropolitan districts, non-metropolitan districts and London boroughs. In Wales they are known as unitary authorities, in Scotland as council districts and in Northern Ireland as local government districts. Further information can be found in the 'geography guide' worksheet. | C6: No Link
A7: 5 | B7: Use of 2024 Local authorities: this spreadsheet uses boundaries for England and Wales that existed at publication, which includes the changes made in April 2023. | C7: No Link
A8: 6 | B8: Revisions to mid-2022 to mid-2024 population estimates: Population estimates for mid-2022, mid-2023 and mid-2024 have been revised to account for updated international migration. The impact of revisions is discussed in the accompanying statistical bulletin and the QMG. Comprehensive data on the revisions can be found in tables MYE7 and in the Analysis of population estimates tool. | C8: Analysis of population estimates tool for UK
A9: 7 | B9: Geographical coverage: these statistics cover England and Wales only. Estimates for the whole of the UK, covering mid-2025, will be published later in the year. | C9: No Link
A10: Issues affecting table MYE0 | B10: Note text | C10: No Link
A11: 8 | B11: Uncertainty measures: The uncertainty estimates include potential uncertainty associated with the 2021 Census, international migration and internal migration. The methodology assumes all other components of population change and adjustments contain no error (e.g. births, deaths, static populations, asylum seekers, visitor switchers, boundary and reconciliation adjustments). | C11: No Link
A12: 9 | B12: Confidence intervals: The unrounded confidence intervals are published to enable further analysis. However, the confidence intervals should not be taken to be accurate to the level of detail provided. | C12: No Link
A13: 10 | B13: Admin Based Migration Estimates: for Admin Based Migration Estimates (ABME), the ONS is progressing with the development of methods to quantify uncertainty with the ABME process. We have developed a simulation based approach for the headline Long Term International Migration (LTIM) uncertainty from ABMEs: Measuring uncertainty in international migration estimates - Office for National Statistics (ons.gov.uk). However, the method only covers some sources of uncertainty with ABMEs (adjustments, modelling, and sampling variability). We have recognised that these uncertainty intervals are partial and likely overconfident with respect to uncertainty associated with ABMEs. | C13: Measuring uncertainty in international migration estimates - Office for National Statistics (ons.gov.uk).
A14: 11 | B14: Scaling factors: In order to calculate uncertainty for internal migration, a benchmark approach is used treating the 2021 Census transitions as the gold standard and comparing these transitions to the 2021 Personal Demographic Service (PDS) transitions. There exists a time difference between the normal Census cutoff date (March 21st) and the PDS cutoff date (June 30th) so to generate the initial full years’ worth of uncertainty, a new version of the 2021 PDS transitions was created aligning with the 2021 Census transitions dates. This comparison creates an element of error in the PDS transitions known as scaling factors. These scaling factors are then clustered based on identifying local authorities with a similar error pattern and then fitted to a generalized additive model (GAM) and resampled 1000 times. We resample the residuals from the models and use them to generate 1000 plausible PDS transition estimates for the future years of interest. Upper and lower bounds are then derived from the 1000 estimates. | C14: Methodology for measuring uncertainty in ONS local authority mid-year population estimates: 2012 to 2016 - Office for National Statistics
A15: 12 | B15: Census uncertainty: we aim to incorporate census uncertainty by using the census bootstrapped estimates, rather than the census estimate for local authorities. Quality assurance found there was a discrepancy between the census bootstrapped estimates and the census point estimates, which is the starting point for the MYE components of change. Overall, we found that the census bootstrapped estimates were systematically lower than the census point estimates. The result was that over 50% of the MYEs were outside of their uncertainty intervals for YE June 2021. An upward adjustment was applied to the census bootstrapped estimates to mitigate against the discrepancy while retaining the variance from the bootstrapped estimates. | C15: No Link
A16: 13 | B16: Bias-adjusted confidence intervals at local authority level: bias-adjusted confidence intervals are calculated as the mid-year estimate plus or minus 1.96 multiplied by RMSE. The RMSE is the variability of the simulated values around the MYE. This confidence interval will be symmetric about the MYE and will include a measure of uncertainty due to bias between the MYE and the simulations. Bias adjusted confidence intervals are the preferred measure of statistical uncertainty for the mid-year estimates but two other versions, empirical and centred are produced. Bias adjusted confidence intervals are often wider than the empirical and centred intervals. | C16: Guidance on interpreting the statistical measures of uncertainty in ONS local authority mid-year population estimates
A17: 14 | B17: Centred confidence intervals for England and Wales: Centred empirical confidence intervals are created by moving the empirical 95% confidence intervals so that they are centred about the observed MYEs. The difference between the median of the simulated values and the observed MYE is subtracted from each of the lower and upper bounds. While the width of the confidence interval remains the same it does not account for the bias component due to the difference between the MYE and the median of the simulation. We recommend using centred confidence intervals for England and Wales | C17: Guidance on interpreting the statistical measures of uncertainty in ONS local authority mid-year population estimates
A18: 15 | B18: Aiding understanding: uncertainty measures for mid-year estimates are presented to aid users in understanding the precision of mid-year estimates but are still research. Further information is available from our Quality Information dataset. | C18: Population estimates: quality information - Office for National Statistics
A19: Issues affecting tables MYE1-7 | B19: Note text
A20: 16 | B20: Accredited Official Statistics: these estimates are accredited official statistics as they have been assessed against the quality standards required for accredited official statistics status. | C20: No Link
A21: Issues affecting table MYE3 | B21: Note text | C21: No Link
A22: 17 | B22: Internal migration: residential moves between different local authority districts in the UK, including those that cross the boundaries between the four UK nations: England, Wales, Scotland and Northern Ireland. Internal migration figures for Northern Ireland include flows to and from the Isle of Man. This means that net internal migration at UK level will not sum to zero. | C22: No Link
A23: 18 | B23: Other changes: changes to the size of armed forces stationed in the UK and other special population adjustments. At geographies higher than local authority, adjustments due to rounding may also be included. This means that other changes at local authority level may not sum to other changes at national level. | C23: No Link
A24: Issues affecting table MYE5 | B24: Note text | C24: No Link
A25: 19 | B25: Rounding: the population density estimates and area measurements are displayed rounded to the nearest integer though calculations have been performed on the unrounded data. | C25: No Link
A26: 20 | B26: Definitions: Standard Area Measurements (SAM) data used reflect the position as at January 2025 for England, Wales and Scotland. Land area measurements, excluding inland water, have been used in compiling these population density figures. Information on this is available from the ONS geography portal. | C26: No Link
A27: 21 | B27: Changes: the area measurements are a definitive set derived from boundaries maintained by Ordnance Survey and Ordnance Survey of Northern Ireland. The current measurements may differ from those published previously in tables, publications, or other statistical outputs, even allowing for boundary changes or changes to the physical structure of the land because of improvements to the source of the data. | C27: No Link
A28: Issues affecting table MYE 7 | B28: Note text | C28: No Link
A29: 22 | B29: MYE7 Summary revisions: As part of the 29 July release of Mid-2025 population estimates for England and Wales we have made revisions to mid-2022 to mid-2024 estimates. These revisions allow for updated international migration estimates to be used. The impact of revisions is discussed in the accompanying Statistical bulletin, QMG and in the Analysis of population estimates tool. | C29: Analysis of population estimates tool for UK

Sheet Geography guide
A1: Geography guide
A2: Tables MYE2-7 contain estimates for England and Wales, regions and counties, and all types of local authority area.
A3: Filter and select the following types of areas on a table's 'geography' column in order to get a certain type of local authority:
A4: Lower tier-only authorities | B4: Local authority districts, metropolitan districts, and non-metropolitan districts
A5: Upper tier-only authorities | B5: Counties and metropolitan counties
A6: Upper and lower tier authorities | B6: Council areas, local government districts, London boroughs, and unitary authority districts
A7: For more information see links in the cells below:
A8: ONS Geoportal
A9: ONS administrative geography pages

Sheet Related publications
A1: Related publications
A2: Further information about population estimates can be found on the Office for National Statistics (ONS) website and elsewhere via the links included below:
A3: Population estimates for England and Wales - Statistical bulletins
A4: Population estimates for UK, England and Wales, Scotland and Northern Ireland - Statistical bulletins
A5: Population estimates for UK, England and Wales, Scotland and Northern Ireland - Datasets
A6: Population estimates for England and Wales - Datasets
A7: NOMIS (a website that allows you to extract population totals by specific ages, places and years)
A8: Analysis of population estimates tool
A9: Population estimates quality tools
A10: Measures of statistical uncertainty summary
A11: Scotland mid-year population estimates
A12: Northern Ireland mid-year population estimates
... A16: Population estimates for England and Wales QMG

Sheet MYE0
A1: MYE0: Population estimates and Research-based measures of statistical uncertainty: Summary for England and Wales, mid-2021 to mid-2025
A2: This worksheet contains one table. Freeze panes are turned on.
A3: To turn off freeze panes select the 'View' ribbon then 'Freeze Panes' then 'Unfreeze Panes' or use [Alt W, F]
A4: Please choose from the links presented in the cells below to e-mail us your opinion on this table:
A5: This met my needs, please produce it next year
A6: I need something slightly different (please specify)
A7: This is not what I need all all (please specify)
A8: Code | B8: Name | C8: Geography | D8: Mid-2025 | E8: Mid-2025 95% research-based confidence interval - lower bound | F8: Mid-2025 95% research-based confidence interval - upper bound | G8: Mid-2024 | H8: Mid-2024 95% research-based confidence interval - lower bound | I8: Mid-2024 95% research-based confidence interval - upper bound | J8: Mid-2023 | K8: Mid-2023 95% research-based confidence interval - lower bound | L8: Mid-2023 95% research-based confidence interval - upper bound | M8: Mid-2022 | N8: Mid-2022 95% research-based confidence interval - lower bound | O8: Mid-2022 95% research-based confidence interval - upper bound | P8: Mid-2021 | Q8: Mid-2021 95% research-based confidence interval - lower bound | R8: Mid-2021 95% research-based confidence interval - upper bound
A9: K04000001 | B9: ENGLAND AND WALES | C9: =VLOOKUP(Table72[[#This Row],[Name]],'MYE2 - Females'!B:C,2,0) -> Country | D9: 62009993 | E9: 61634778 | F9: 62667695 | G9: 61785119 | H9: 61474278 | I9: 62289131 | J9: 61155866 | K9: 60885759 | L9: 61526337 | M9: 60322431 | N9: 60089428 | O9: 60580433 | P9: 59660524 | Q9: 59455784 | R9: 59876537
A10: E06000001 | B10: Hartlepool | C10: =VLOOKUP(Table72[[#This Row],[Name]],'MYE2 - Females'!B:C,2,0) -> Unitary Authority | D10: 99656 | E10: 97409.206 | F10: 101902.79 | G10: 97868 | H10: 95885.316 | I10: 99850.684 | J10: 95717 | K10: 93923.6 | L10: 97510.4 | M10: 94058 | N10: 92338.767 | O10: 95777.233 | P10: 92575 | Q10: 90862.672 | R10: 94287.328
A11: E06000002 | B11: Middlesbrough | C11: =VLOOKUP(Table72[[#This Row],[Name]],'MYE2 - Females'!B:C,2,0) -> Unitary Authority | D11: 152795 | E11: 147232.13 | F11: 158357.87 | G11: 154700 | H11: 150136.73 | I11: 159263.27 | J11: 153186 | K11: 149259.82 | L11: 157112.18 | M11: 149095 | N11: 145514.84 | O11: 152675.16 | P11: 143943 | Q11: 140388.41 | R11: 147497.59
A12: E06000003 | B12: Redcar and Cleveland | C12: =VLOOKUP(Table72[[#This Row],[Name]],'MYE2 - Females'!B:C,2,0) -> Unitary Authority | D12: 139541 | E12: 137195.27 | F12: 141886.73 | G12: 138788 | H12: 136658.66 | I12: 140917.34 | J12: 137810 | K12: 135856.56 | L12: 139763.44 | M12: 137087 | N12: 135243.73 | O12: 138930.27 | P12: 136605 | Q12: 134823.71 | R12: 138386.29
A13: E06000004 | B13: Stockton-on-Tees | C13: =VLOOKUP(Table72[[#This Row],[Name]],'MYE2 - Females'!B:C,2,0) -> Unitary Authority | D13: 207158 | E13: 203606.38 | F13: 210709.62 | G13: 206018 | H13: 203052.1 | I13: 208983.9 | J13: 203361 | K13: 200892.84 | L13: 205829.16 | M13: 200573 | N13: 198571.36 | O13: 202574.64 | P13: 197032 | Q13: 195210.35 | R13: 198853.65
A14: E06000005 | B14: Darlington | C14: =VLOOKUP(Table72[[#This Row],[Name]],'MYE2 - Females'!B:C,2,0) -> Unitary Authority | D14: 113402 | E14: 111153.12 | F14: 115650.88 | G14: 112150 | H14: 110253.82 | I14: 114046.18 | J14: 110776 | K14: 109332.18 | L14: 112219.82 | M14: 109364 | N14: 108272.24 | O14: 110455.76 | P14: 108210 | Q14: 107235.95 | R14: 109184.05
A15: E06000006 | B15: Halton | C15: =VLOOKUP(Table72[[#This Row],[Name]],'MYE2 - Females'!B:C,2,0) -> Unitary Authority | D15: 131912 | E15: 129791.9 | F15: 134032.1 | G15: 131247 | H15: 129492.39 | I15: 133001.61 | J15: 130202 | K15: 128691.23 | L15: 131712.77 | M15: 129362 | N15: 128019.13 | O15: 130704.87 | P15: 128570 | Q15: 127260.53 | R15: 129879.47
A16: E06000007 | B16: Warrington | C16: =VLOOKUP(Table72[[#This Row],[Name]],'MYE2 - Females'!B:C,2,0) -> Unitary Authority | D16: 215425 | E16: 210622.43 | F16: 220227.57 | G16: 214640 | H16: 210605.5 | I16: 218674.5 | J16: 213242 | K16: 210114.89 | L16: 216369.11 | M16: 211546 | N16: 209101.57 | O16: 213990.43 | P16: 211182 | Q16: 208954.38 | R16: 213409.62
A17: E06000008 | B17: Blackburn with Darwen | C17: =VLOOKUP(Table72[[#This Row],[Name]],'MYE2 - Females'!B:C,2,0) -> Unitary Authority | D17: 163801 | E17: 159889.28 | F17: 167712.72 | G17: 161618 | H17: 157891.11 | I17: 165344.89 | J17: 158543 | K17: 154970.79 | L17: 162115.21 | M17: 155987 | N17: 152466.66 | O17: 159507.34 | P17: 154954 | Q17: 151422.53 | R17: 158485.47
A18: E06000009 | B18: Blackpool | C18: =VLOOKUP(Table72[[#This Row],[Name]],'MYE2 - Females'!B:C,2,0) -> Unitary Authority | D18: 143492 | E18: 140506.48 | F18: 146477.52 | G18: 143353 | H18: 140561.41 | I18: 146144.59 | J18: 142525 | K18: 139884.58 | L18: 145165.42 | M18: 141442 | N18: 138873.79 | O18: 144010.21 | P18: 140976 | Q18: 138428.33 | R18: 143523.67
A19: E06000010 | B19: Kingston upon Hull, City of | C19: =VLOOKUP(Table72[[#This Row],[Name]],'MYE2 - Females'!B:C,2,0) -> Unitary Authority | D19: 273257 | E19: 265622.65 | F19: 280891.35 | G19: 274727 | H19: 268615.2 | I19: 280838.8 | J19: 273245 | K19: 267776.01 | L19: 278713.99 | M19: 269026 | N19: 264099 | O19: 273953 | P19: 266516 | Q19: 261824.45 | R19: 271207.55
A20: E06000011 | B20: East Riding of Yorkshire | C20: =VLOOKUP(Table72[[#This Row],[Name]],'MYE2 - Females'!B:C,2,0) -> Unitary Authority | D20: 360334 | E20: 351726.97 | F20: 368941.03 | G20: 355378 | H20: 348987.51 | I20: 361768.49 | J20: 351030 | K20: 346268.91 | L20: 355791.09 | M20: 346506 | N20: 343148.82 | O20: 349863.18 | P20: 343145 | Q20: 340644.75 | R20: 345645.25
... A327: W06000024 | B327: Merthyr Tydfil | C327: =VLOOKUP(Table72[[#This Row],[Name]],'MYE2 - Females'!B:C,2,0) -> Unitary Authority | D327: 58362 | E327: 55040.191 | F327: 61683.809 | G327: 58722 | H327: 55493.97 | I327: 61950.03 | J327: 58735 | K327: 55407.233 | L327: 62062.767 | M327: 58866 | N327: 55624.236 | O327: 62107.764 | P327: 58869 | Q327: 55540.927 | R327: 62197.073

Sheet MYE1
A1: MYE1: Population estimates: Summary for England and Wales, mid-2025
A2: This worksheet contains one table.
A3: Please choose from the links presented in the cells below to e-mail us your opinion on this table:
A4: This met my needs, please produce it next year
A5: I need something slightly different (please specify)
A6: This is not what I need all all (please specify)
A7: Groups/Codes | B7: England and Wales | C7: England | D7: Wales
A8: Country Code | B8: K04000001 | C8: E92000001 | D8: W92000004
A9: All Persons | B9: 62009993 | C9: 58834812 | D9: 3175181
A10: Females | B10: 31615275 | C10: 29994357 | D10: 1620918
A11: Males | B11: 30394718 | C11: 28840455 | D11: 1554263
A12: Age Groups | B12: No data | C12: No data | D12: No data
A13: 0 to 4 | B13: 3147970 | C13: 3003917 | D13: 144053
A14: 5 to 9 | B14: 3479089 | C14: 3311011 | D14: 168078
A15: 10 to 14 | B15: 3699243 | C15: 3515075 | D15: 184168
A16: 15 to 19 | B16: 3678620 | C16: 3496152 | D16: 182468
A17: 20 to 24 | B17: 3718400 | C17: 3532068 | D17: 186332
A18: 25 to 29 | B18: 4054104 | C18: 3863860 | D18: 190244
A19: 30 to 34 | B19: 4271101 | C19: 4070483 | D19: 200618
A20: 35 to 39 | B20: 4337695 | C20: 4131479 | D20: 206216
A21: 40 to 44 | B21: 4101988 | C21: 3908112 | D21: 193876
A22: 45 to 49 | B22: 3747757 | C22: 3570762 | D22: 176995
A23: 50 to 54 | B23: 3869925 | C23: 3673825 | D23: 196100
A24: 55 to 59 | B24: 4073123 | C24: 3853737 | D24: 219386
... A31: 90 and over | B31: 581414 | C31: 549750 | D31: 31664

Sheet MYE2 - Persons
A1: MYE2: Persons by single year of age and sex for local authorities in England and Wales, mid-2025
A2: This worksheet contains one table. Freeze panes are turned on.
A3: To turn off freeze panes select the 'View' ribbon then 'Freeze Panes' then 'Unfreeze Panes' or use [Alt W, F]
A4: Please choose from the links presented in the cells below to e-mail us your opinion on this table:
A5: This met my needs, please produce it next year
A6: I need something slightly different (please specify)
A7: This is not what I need at all (please specify)
A8: Code | B8: Name | C8: Geography | D8: All ages | E8: 0 | F8: 1 | G8: 2 | H8: 3 | I8: 4 | J8: 5 | K8: 6 | L8: 7 | M8: 8 | N8: 9 | O8: 10 | P8: 11 | Q8: 12 | R8: 13 | S8: 14 | T8: 15 | U8: 16 | V8: 17 | W8: 18 | X8: 19 | Y8: 20 | Z8: 21 | AA8: 22 | AB8: 23 | AC8: 24 | AD8: 25 | AE8: 26 | AF8: 27 | AG8: 28 | AH8: 29 | AI8: 30 | AJ8: 31 | AK8: 32 | AL8: 33 | AM8: 34 | AN8: 35 | AO8: 36 | AP8: 37 | AQ8: 38 | AR8: 39 | AS8: 40 | AT8: 41 | AU8: 42 | AV8: 43 | AW8: 44 | AX8: 45 | AY8: 46 | AZ8: 47 | BA8: 48 | BB8: 49 | BC8: 50 | BD8: 51 | BE8: 52 | BF8: 53 | BG8: 54 | BH8: 55 | BI8: 56 | BJ8: 57 | BK8: 58 | BL8: 59 | BM8: 60 | BN8: 61 | BO8: 62 | BP8: 63 | BQ8: 64 | BR8: 65 | BS8: 66 | BT8: 67 | BU8: 68 | BV8: 69 | BW8: 70 | BX8: 71 | BY8: 72 | BZ8: 73 | CA8: 74 | CB8: 75 | CC8: 76 | CD8: 77 | CE8: 78 | CF8: 79 | CG8: 80 | CH8: 81 | CI8: 82 | CJ8: 83 | CK8: 84 | CL8: 85 | CM8: 86 | CN8: 87 | CO8: 88 | CP8: 89 | CQ8: 90+
A9: K04000001 | B9: ENGLAND AND WALES | C9: Country | D9: 62009993 | E9: 593467 | F9: 611933 | G9: 627510 | H9: 663236 | I9: 651824 | J9: 671110 | K9: 682406 | L9: 691836 | M9: 707619 | N9: 726118 | O9: 719681 | P9: 723292 | Q9: 740126 | R9: 758159 | S9: 757985 | T9: 747386 | U9: 742014 | V9: 750819 | W9: 721968 | X9: 716433 | Y9: 727989 | Z9: 729148 | AA9: 738135 | AB9: 758534 | AC9: 764594 | AD9: 781394 | AE9: 804408 | AF9: 816442 | AG9: 832953 | AH9: 818907 | AI9: 828919 | AJ9: 846900 | AK9: 847530 | AL9: 868529 | AM9: 879223 | AN9: 878568 | AO9: 870735 | AP9: 878935 | AQ9: 858048 | AR9: 851409 | AS9: 845714 | AT9: 817069 | AU9: 815806 | AV9: 808755 | AW9: 814644 | AX9: 814885 | AY9: 779056 | AZ9: 723253 | BA9: 708944 | BB9: 721619 | BC9: 735170 | BD9: 742093 | BE9: 769701 | BF9: 797201 | BG9: 825760 | BH9: 803220 | BI9: 820108 | BJ9: 815578 | BK9: 819633 | BL9: 814584 | BM9: 815321 | BN9: 802867 | BO9: 781769 | BP9: 761190 | BQ9: 730375 | BR9: 697905 | BS9: 676441 | BT9: 653833 | BU9: 623501 | BV9: 595258 | BW9: 568471 | BX9: 565046 | BY9: 550644 | BZ9: 528646 | CA9: 525676 | CB9: 526288 | CC9: 531002 | CD9: 551917 | CE9: 585847 | CF9: 436293 | CG9: 411260 | CH9: 395668 | CI9: 351861 | CJ9: 300648 | CK9: 254772 | CL9: 249662 | CM9: 231931 | CN9: 209005 | CO9: 181337 | CP9: 155130 | CQ9: 581414
A10: E92000001 | B10: ENGLAND | C10: Country | D10: 58834812 | E10: 566856 | F10: 583995 | G10: 598812 | H10: 632519 | I10: 621735 | J10: 639573 | K10: 649939 | L10: 658100 | M10: 673250 | N10: 690149 | O10: 684090 | P10: 687461 | Q10: 703335 | R10: 720398 | S10: 719791 | T10: 709747 | U10: 704742 | V10: 713111 | W10: 687226 | X10: 681326 | Y10: 690970 | Z10: 693051 | AA10: 700895 | AB10: 720300 | AC10: 726852 | AD10: 743962 | AE10: 766437 | AF10: 778835 | AG10: 793589 | AH10: 781037 | AI10: 790457 | AJ10: 807450 | AK10: 808007 | AL10: 827384 | AM10: 837185 | AN10: 837149 | AO10: 829515 | AP10: 836857 | AQ10: 816950 | AR10: 811008 | AS10: 805453 | AT10: 778678 | AU10: 777075 | AV10: 770610 | AW10: 776296 | AX10: 776061 | AY10: 742384 | AZ10: 689455 | BA10: 675496 | BB10: 687366 | BC10: 699589 | BD10: 705493 | BE10: 730862 | BF10: 755961 | BG10: 781920 | BH10: 761001 | BI10: 775861 | BJ10: 771871 | BK10: 775012 | BL10: 769992 | BM10: 769540 | BN10: 757254 | BO10: 737259 | BP10: 717537 | BQ10: 688350 | BR10: 657312 | BS10: 636642 | BT10: 615252 | BU10: 586508 | BV10: 560017 | BW10: 534755 | BX10: 530809 | BY10: 516808 | BZ10: 496761 | CA10: 493766 | CB10: 494182 | CC10: 498886 | CD10: 518625 | CE10: 551594 | CF10: 410826 | CG10: 386927 | CH10: 372527 | CI10: 331150 | CJ10: 282492 | CK10: 239309 | CL10: 235397 | CM10: 219053 | CN10: 197365 | CO10: 171195 | CP10: 146483 | CQ10: 549750
A11: E12000001 | B11: NORTH EAST | C11: Region | D11: 2762746 | E11: 24571 | F11: 25666 | G11: 26229 | H11: 27701 | I11: 27287 | J11: 27851 | K11: 29000 | L11: 29417 | M11: 30479 | N11: 31255 | O11: 30765 | P11: 31319 | Q11: 32158 | R11: 32537 | S11: 32805 | T11: 32236 | U11: 31634 | V11: 32718 | W11: 32440 | X11: 37523 | Y11: 38121 | Z11: 37204 | AA11: 35690 | AB11: 33124 | AC11: 31912 | AD11: 31507 | AE11: 31775 | AF11: 32576 | AG11: 33847 | AH11: 33321 | AI11: 34203 | AJ11: 34926 | AK11: 35306 | AL11: 36837 | AM11: 36830 | AN11: 36257 | AO11: 36064 | AP11: 36979 | AQ11: 36267 | AR11: 36497 | AS11: 35871 | AT11: 34499 | AU11: 34113 | AV11: 33612 | AW11: 33764 | AX11: 34062 | AY11: 32805 | AZ11: 29321 | BA11: 27969 | BB11: 29866 | BC11: 30437 | BD11: 30750 | BE11: 32766 | BF11: 35387 | BG11: 37451 | BH11: 35541 | BI11: 36337 | BJ11: 37188 | BK11: 37978 | BL11: 38501 | BM11: 39060 | BN11: 38514 | BO11: 38442 | BP11: 38083 | BQ11: 36244 | BR11: 35098 | BS11: 35083 | BT11: 34282 | BU11: 32658 | BV11: 31249 | BW11: 29677 | BX11: 29127 | BY11: 28364 | BZ11: 26961 | CA11: 26451 | CB11: 26285 | CC11: 26370 | CD11: 27178 | CE11: 28718 | CF11: 20688 | CG11: 19257 | CH11: 17957 | CI11: 15299 | CJ11: 13518 | CK11: 11956 | CL11: 11717 | CM11: 10755 | CN11: 9739 | CO11: 8623 | CP11: 6979 | CQ11: 25362
A12: E06000047 | B12: County Durham | C12: Unitary Authority | D12: 539146 | E12: 4384 | F12: 4784 | G12: 4676 | H12: 4924 | I12: 4942 | J12: 5135 | K12: 5236 | L12: 5357 | M12: 5469 | N12: 5807 | O12: 5757 | P12: 5971 | Q12: 6065 | R12: 6106 | S12: 6218 | T12: 6124 | U12: 5898 | V12: 6153 | W12: 6580 | X12: 9038 | Y12: 9240 | Z12: 8572 | AA12: 8185 | AB12: 6285 | AC12: 5588 | AD12: 5339 | AE12: 5464 | AF12: 5588 | AG12: 5851 | AH12: 5810 | AI12: 5964 | AJ12: 6053 | AK12: 6248 | AL12: 6495 | AM12: 6658 | AN12: 6557 | AO12: 6481 | AP12: 6676 | AQ12: 6510 | AR12: 6606 | AS12: 6502 | AT12: 6328 | AU12: 6489 | AV12: 6390 | AW12: 6406 | AX12: 6388 | AY12: 6331 | AZ12: 5738 | BA12: 5406 | BB12: 5715 | BC12: 5936 | BD12: 6074 | BE12: 6799 | BF12: 7291 | BG12: 7747 | BH12: 7276 | BI12: 7719 | BJ12: 7898 | BK12: 8023 | BL12: 8094 | BM12: 8249 | BN12: 8068 | BO12: 7864 | BP12: 7848 | BQ12: 7376 | BR12: 6963 | BS12: 7189 | BT12: 6874 | BU12: 6546 | BV12: 6299 | BW12: 6166 | BX12: 5978 | BY12: 5820 | BZ12: 5483 | CA12: 5562 | CB12: 5389 | CC12: 5502 | CD12: 5528 | CE12: 5868 | CF12: 4291 | CG12: 4100 | CH12: 3896 | CI12: 3222 | CJ12: 2744 | CK12: 2511 | CL12: 2366 | CM12: 2135 | CN12: 1905 | CO12: 1780 | CP12: 1432 | CQ12: 4848
A13: E06000005 | B13: Darlington | C13: Unitary Authority | D13: 113402 | E13: 1099 | F13: 1092 | G13: 1086 | H13: 1183 | I13: 1130 | J13: 1199 | K13: 1201 | L13: 1235 | M13: 1216 | N13: 1270 | O13: 1307 | P13: 1346 | Q13: 1385 | R13: 1418 | S13: 1376 | T13: 1392 | U13: 1434 | V13: 1416 | W13: 1313 | X13: 949 | Y13: 923 | Z13: 921 | AA13: 1021 | AB13: 1066 | AC13: 1086 | AD13: 1268 | AE13: 1374 | AF13: 1476 | AG13: 1420 | AH13: 1476 | AI13: 1416 | AJ13: 1445 | AK13: 1566 | AL13: 1507 | AM13: 1633 | AN13: 1444 | AO13: 1512 | AP13: 1649 | AQ13: 1451 | AR13: 1529 | AS13: 1415 | AT13: 1433 | AU13: 1461 | AV13: 1442 | AW13: 1450 | AX13: 1424 | AY13: 1440 | AZ13: 1314 | BA13: 1242 | BB13: 1313 | BC13: 1344 | BD13: 1386 | BE13: 1405 | BF13: 1529 | BG13: 1593 | BH13: 1535 | BI13: 1530 | BJ13: 1533 | BK13: 1544 | BL13: 1623 | BM13: 1642 | BN13: 1541 | BO13: 1597 | BP13: 1556 | BQ13: 1504 | BR13: 1383 | BS13: 1401 | BT13: 1369 | BU13: 1281 | BV13: 1255 | BW13: 1186 | BX13: 1160 | BY13: 1165 | BZ13: 1096 | CA13: 1048 | CB13: 1049 | CC13: 1121 | CD13: 1106 | CE13: 1237 | CF13: 900 | CG13: 855 | CH13: 733 | CI13: 642 | CJ13: 558 | CK13: 546 | CL13: 533 | CM13: 495 | CN13: 425 | CO13: 356 | CP13: 305 | CQ13: 1171
A14: E06000001 | B14: Hartlepool | C14: Unitary Authority | D14: 99656 | E14: 978 | F14: 999 | G14: 1034 | H14: 1080 | I14: 1054 | J14: 1135 | K14: 1163 | L14: 1137 | M14: 1205 | N14: 1246 | O14: 1160 | P14: 1256 | Q14: 1255 | R14: 1278 | S14: 1296 | T14: 1281 | U14: 1280 | V14: 1342 | W14: 1203 | X14: 1075 | Y14: 1053 | Z14: 1107 | AA14: 943 | AB14: 1034 | AC14: 1230 | AD14: 1198 | AE14: 1293 | AF14: 1136 | AG14: 1278 | AH14: 1168 | AI14: 1306 | AJ14: 1282 | AK14: 1237 | AL14: 1429 | AM14: 1309 | AN14: 1271 | AO14: 1326 | AP14: 1353 | AQ14: 1375 | AR14: 1259 | AS14: 1297 | AT14: 1256 | AU14: 1154 | AV14: 1199 | AW14: 1166 | AX14: 1158 | AY14: 1113 | AZ14: 1057 | BA14: 1010 | BB14: 1054 | BC14: 1020 | BD14: 1065 | BE14: 1199 | BF14: 1256 | BG14: 1372 | BH14: 1315 | BI14: 1307 | BJ14: 1369 | BK14: 1434 | BL14: 1442 | BM14: 1450 | BN14: 1394 | BO14: 1462 | BP14: 1437 | BQ14: 1412 | BR14: 1256 | BS14: 1311 | BT14: 1136 | BU14: 1193 | BV14: 1093 | BW14: 1046 | BX14: 951 | BY14: 983 | BZ14: 979 | CA14: 899 | CB14: 958 | CC14: 921 | CD14: 926 | CE14: 957 | CF14: 669 | CG14: 602 | CH14: 550 | CI14: 424 | CJ14: 454 | CK14: 377 | CL14: 402 | CM14: 349 | CN14: 358 | CO14: 298 | CP14: 209 | CQ14: 913
A15: E06000002 | B15: Middlesbrough | C15: Unitary Authority | D15: 152795 | E15: 1866 | F15: 1874 | G15: 1916 | H15: 1900 | I15: 1776 | J15: 1776 | K15: 1846 | L15: 1865 | M15: 2025 | N15: 1865 | O15: 1980 | P15: 1936 | Q15: 2075 | R15: 2021 | S15: 2063 | T15: 1997 | U15: 1784 | V15: 1939 | W15: 1845 | X15: 1872 | Y15: 1916 | Z15: 2006 | AA15: 2011 | AB15: 2123 | AC15: 2276 | AD15: 2270 | AE15: 2049 | AF15: 2453 | AG15: 2370 | AH15: 2388 | AI15: 2292 | AJ15: 2354 | AK15: 2289 | AL15: 2498 | AM15: 2241 | AN15: 2255 | AO15: 2308 | AP15: 2218 | AQ15: 2289 | AR15: 2258 | AS15: 2113 | AT15: 2091 | AU15: 1918 | AV15: 1749 | AW15: 1834 | AX15: 1851 | AY15: 1719 | AZ15: 1470 | BA15: 1423 | BB15: 1490 | BC15: 1527 | BD15: 1479 | BE15: 1577 | BF15: 1612 | BG15: 1691 | BH15: 1660 | BI15: 1614 | BJ15: 1775 | BK15: 1738 | BL15: 1822 | BM15: 1809 | BN15: 1791 | BO15: 1802 | BP15: 1879 | BQ15: 1740 | BR15: 1679 | BS15: 1666 | BT15: 1677 | BU15: 1608 | BV15: 1492 | BW15: 1434 | BX15: 1286 | BY15: 1333 | BZ15: 1217 | CA15: 1162 | CB15: 1129 | CC15: 1092 | CD15: 1094 | CE15: 1218 | CF15: 856 | CG15: 800 | CH15: 704 | CI15: 649 | CJ15: 633 | CK15: 534 | CL15: 503 | CM15: 454 | CN15: 425 | CO15: 352 | CP15: 314 | CQ15: 1225
A16: E06000057 | B16: Northumberland | C16: Unitary Authority | D16: 333975 | E16: 2436 | F16: 2648 | G16: 2737 | H16: 2833 | I16: 3004 | J16: 2927 | K16: 3148 | L16: 3295 | M16: 3361 | N16: 3499 | O16: 3423 | P16: 3547 | Q16: 3601 | R16: 3729 | S16: 3732 | T16: 3607 | U16: 3542 | V16: 3724 | W16: 3303 | X16: 2784 | Y16: 2454 | Z16: 2369 | AA16: 2792 | AB16: 2927 | AC16: 3087 | AD16: 3105 | AE16: 3200 | AF16: 3318 | AG16: 3140 | AH16: 3346 | AI16: 3420 | AJ16: 3495 | AK16: 3620 | AL16: 3743 | AM16: 3835 | AN16: 3752 | AO16: 3719 | AP16: 3920 | AQ16: 3869 | AR16: 3772 | AS16: 3987 | AT16: 3735 | AU16: 3735 | AV16: 3791 | AW16: 3748 | AX16: 4046 | AY16: 3880 | AZ16: 3431 | BA16: 3437 | BB16: 3719 | BC16: 3886 | BD16: 3954 | BE16: 4232 | BF16: 4634 | BG16: 4908 | BH16: 4616 | BI16: 4811 | BJ16: 5012 | BK16: 5188 | BL16: 5264 | BM16: 5583 | BN16: 5528 | BO16: 5468 | BP16: 5481 | BQ16: 5228 | BR16: 5339 | BS16: 5180 | BT16: 5027 | BU16: 4876 | BV16: 4789 | BW16: 4526 | BX16: 4467 | BY16: 4394 | BZ16: 4206 | CA16: 4121 | CB16: 4154 | CC16: 4140 | CD16: 4448 | CE16: 4619 | CF16: 3288 | CG16: 3091 | CH16: 2910 | CI16: 2512 | CJ16: 2104 | CK16: 1833 | CL16: 1748 | CM16: 1563 | CN16: 1393 | CO16: 1306 | CP16: 1065 | CQ16: 3811
A17: E06000003 | B17: Redcar and Cleveland | C17: Unitary Authority | D17: 139541 | E17: 1160 | F17: 1242 | G17: 1320 | H17: 1462 | I17: 1290 | J17: 1420 | K17: 1456 | L17: 1421 | M17: 1576 | N17: 1536 | O17: 1604 | P17: 1599 | Q17: 1711 | R17: 1772 | S17: 1752 | T17: 1620 | U17: 1592 | V17: 1654 | W17: 1605 | X17: 1362 | Y17: 1184 | Z17: 1219 | AA17: 1206 | AB17: 1312 | AC17: 1375 | AD17: 1413 | AE17: 1478 | AF17: 1399 | AG17: 1419 | AH17: 1458 | AI17: 1517 | AJ17: 1597 | AK17: 1597 | AL17: 1689 | AM17: 1736 | AN17: 1626 | AO17: 1664 | AP17: 1661 | AQ17: 1662 | AR17: 1660 | AS17: 1764 | AT17: 1553 | AU17: 1518 | AV17: 1606 | AW17: 1616 | AX17: 1653 | AY17: 1501 | AZ17: 1405 | BA17: 1323 | BB17: 1476 | BC17: 1476 | BD17: 1569 | BE17: 1686 | BF17: 1844 | BG17: 2045 | BH17: 1975 | BI17: 2027 | BJ17: 2002 | BK17: 2234 | BL17: 2297 | BM17: 2200 | BN17: 2116 | BO17: 2196 | BP17: 2163 | BQ17: 2012 | BR17: 1952 | BS17: 1949 | BT17: 1947 | BU17: 1759 | BV17: 1752 | BW17: 1625 | BX17: 1686 | BY17: 1631 | BZ17: 1530 | CA17: 1525 | CB17: 1510 | CC17: 1577 | CD17: 1598 | CE17: 1708 | CF17: 1313 | CG17: 1191 | CH17: 1137 | CI17: 894 | CJ17: 894 | CK17: 738 | CL17: 740 | CM17: 692 | CN17: 567 | CO17: 508 | CP17: 427 | CQ17: 1408
A18: E06000004 | B18: Stockton-on-Tees | C18: Unitary Authority | D18: 207158 | E18: 1910 | F18: 2114 | G18: 2083 | H18: 2262 | I18: 2193 | J18: 2346 | K18: 2341 | L18: 2375 | M18: 2592 | N18: 2607 | O18: 2560 | P18: 2575 | Q18: 2785 | R18: 2749 | S18: 2857 | T18: 2724 | U18: 2762 | V18: 2802 | W18: 2561 | X18: 2003 | Y18: 1734 | Z18: 1768 | AA18: 1722 | AB18: 1879 | AC18: 1997 | AD18: 2238 | AE18: 2337 | AF18: 2371 | AG18: 2709 | AH18: 2435 | AI18: 2592 | AJ18: 2867 | AK18: 2798 | AL18: 2939 | AM18: 2938 | AN18: 2896 | AO18: 2916 | AP18: 3037 | AQ18: 2908 | AR18: 3017 | AS18: 2941 | AT18: 2871 | AU18: 2803 | AV18: 2648 | AW18: 2760 | AX18: 2659 | AY18: 2597 | AZ18: 2311 | BA18: 2178 | BB18: 2308 | BC18: 2381 | BD18: 2448 | BE18: 2394 | BF18: 2657 | BG18: 2743 | BH18: 2760 | BI18: 2750 | BJ18: 2784 | BK18: 2831 | BL18: 2811 | BM18: 2733 | BN18: 2755 | BO18: 2798 | BP18: 2777 | BQ18: 2607 | BR18: 2610 | BS18: 2535 | BT18: 2437 | BU18: 2445 | BV18: 2260 | BW18: 2058 | BX18: 2124 | BY18: 1947 | BZ18: 1940 | CA18: 1901 | CB18: 1794 | CC18: 1857 | CD18: 1924 | CE18: 1964 | CF18: 1389 | CG18: 1310 | CH18: 1228 | CI18: 1042 | CJ18: 1025 | CK18: 884 | CL18: 798 | CM18: 747 | CN18: 681 | CO18: 567 | CP18: 439 | CQ18: 1648
A19: E11000007 | B19: Tyne and Wear (Met County) | C19: Metropolitan County | D19: 1177073 | E19: 10738 | F19: 10913 | G19: 11377 | H19: 12057 | I19: 11898 | J19: 11913 | K19: 12609 | L19: 12732 | M19: 13035 | N19: 13425 | O19: 12974 | P19: 13089 | Q19: 13281 | R19: 13464 | S19: 13511 | T19: 13491 | U19: 13342 | V19: 13688 | W19: 14030 | X19: 18440 | Y19: 19617 | Z19: 19242 | AA19: 17810 | AB19: 16498 | AC19: 15273 | AD19: 14676 | AE19: 14580 | AF19: 14835 | AG19: 15660 | AH19: 15240 | AI19: 15696 | AJ19: 15833 | AK19: 15951 | AL19: 16537 | AM19: 16480 | AN19: 16456 | AO19: 16138 | AP19: 16465 | AQ19: 16203 | AR19: 16396 | AS19: 15852 | AT19: 15232 | AU19: 15035 | AV19: 14787 | AW19: 14784 | AX19: 14883 | AY19: 14224 | AZ19: 12595 | BA19: 11950 | BB19: 12791 | BC19: 12867 | BD19: 12775 | BE19: 13474 | BF19: 14564 | BG19: 15352 | BH19: 14404 | BI19: 14579 | BJ19: 14815 | BK19: 14986 | BL19: 15148 | BM19: 15394 | BN19: 15321 | BO19: 15255 | BP19: 14942 | BQ19: 14365 | BR19: 13916 | BS19: 13852 | BT19: 13815 | BU19: 12950 | BV19: 12309 | BW19: 11636 | BX19: 11475 | BY19: 11091 | BZ19: 10510 | CA19: 10233 | CB19: 10302 | CC19: 10160 | CD19: 10554 | CE19: 11147 | CF19: 7982 | CG19: 7308 | CH19: 6799 | CI19: 5914 | CJ19: 5106 | CK19: 4533 | CL19: 4627 | CM19: 4320 | CN19: 3985 | CO19: 3456 | CP19: 2788 | CQ19: 10338
A20: E08000037 | B20: Gateshead | C20: Metropolitan District | D20: 202509 | E20: 1880 | F20: 1857 | G20: 1891 | H20: 2111 | I20: 2048 | J20: 2046 | K20: 2170 | L20: 2176 | M20: 2312 | N20: 2281 | O20: 2402 | P20: 2297 | Q20: 2280 | R20: 2387 | S20: 2428 | T20: 2411 | U20: 2419 | V20: 2432 | W20: 2503 | X20: 2351 | Y20: 2163 | Z20: 1864 | AA20: 1978 | AB20: 2046 | AC20: 2262 | AD20: 2262 | AE20: 2516 | AF20: 2598 | AG20: 2767 | AH20: 2762 | AI20: 2908 | AJ20: 2836 | AK20: 2859 | AL20: 2923 | AM20: 2768 | AN20: 2845 | AO20: 2791 | AP20: 2834 | AQ20: 2753 | AR20: 2872 | AS20: 2708 | AT20: 2728 | AU20: 2709 | AV20: 2473 | AW20: 2604 | AX20: 2647 | AY20: 2475 | AZ20: 2207 | BA20: 2134 | BB20: 2263 | BC20: 2217 | BD20: 2262 | BE20: 2294 | BF20: 2711 | BG20: 2721 | BH20: 2640 | BI20: 2678 | BJ20: 2704 | BK20: 2810 | BL20: 2803 | BM20: 2760 | BN20: 2683 | BO20: 2754 | BP20: 2717 | BQ20: 2547 | BR20: 2409 | BS20: 2434 | BT20: 2467 | BU20: 2331 | BV20: 2075 | BW20: 2073 | BX20: 1962 | BY20: 1972 | BZ20: 1837 | CA20: 1800 | CB20: 1912 | CC20: 1892 | CD20: 1977 | CE20: 2080 | CF20: 1424 | CG20: 1421 | CH20: 1266 | CI20: 1094 | CJ20: 984 | CK20: 895 | CL20: 868 | CM20: 884 | CN20: 748 | CO20: 670 | CP20: 480 | CQ20: 2016
... A365: W06000022 | B365: Newport | C365: Unitary Authority | D365: 168584 | E365: 1794 | F365: 1968 | G365: 1934 | H365: 2093 | I365: 1986 | J365: 2064 | K365: 2148 | L365: 2099 | M365: 2147 | N365: 2335 | O365: 2189 | P365: 2102 | Q365: 2138 | R365: 2065 | S365: 2187 | T365: 2203 | U365: 2189 | V365: 2153 | W365: 1787 | X365: 1404 | Y365: 1366 | Z365: 1392 | AA365: 1560 | AB365: 1767 | AC365: 1911 | AD365: 2066 | AE365: 2192 | AF365: 2282 | AG365: 2413 | AH365: 2365 | AI365: 2504 | AJ365: 2439 | AK365: 2762 | AL365: 2772 | AM365: 2912 | AN365: 2749 | AO365: 2653 | AP365: 2931 | AQ365: 2671 | AR365: 2610 | AS365: 2645 | AT365: 2458 | AU365: 2228 | AV365: 2282 | AW365: 2175 | AX365: 2280 | AY365: 2097 | AZ365: 1952 | BA365: 1887 | BB365: 1893 | BC365: 1858 | BD365: 1907 | BE365: 2015 | BF365: 1983 | BG365: 2190 | BH365: 2082 | BI365: 2163 | BJ365: 2086 | BK365: 2144 | BL365: 2144 | BM365: 2136 | BN365: 2099 | BO365: 2034 | BP365: 1969 | BQ365: 1840 | BR365: 1775 | BS365: 1816 | BT365: 1622 | BU365: 1535 | BV365: 1369 | BW365: 1338 | BX365: 1457 | BY365: 1379 | BZ365: 1263 | CA365: 1166 | CB365: 1268 | CC365: 1254 | CD365: 1321 | CE365: 1375 | CF365: 991 | CG365: 1013 | CH365: 910 | CI365: 825 | CJ365: 756 | CK365: 658 | CL365: 577 | CM365: 551 | CN365: 475 | CO365: 423 | CP365: 343 | CQ365: 1275

Sheet MYE2 - Females
A1: MYE2: Females by single year of age and sex for local authorities in England and Wales, mid-2025
A2: This worksheet contains one table. Freeze panes are turned on.
A3: To turn off freeze panes select the 'View' ribbon then 'Freeze Panes' then 'Unfreeze Panes' or use [Alt W, F]
A4: Please choose from the links presented in the cells below to e-mail us your opinion on this table:
A5: This met my needs, please produce it next year
A6: I need something slightly different (please specify)
A7: This is not what I need at all (please specify)
A8: Code | B8: Name | C8: Geography | D8: All ages | E8: 0 | F8: 1 | G8: 2 | H8: 3 | I8: 4 | J8: 5 | K8: 6 | L8: 7 | M8: 8 | N8: 9 | O8: 10 | P8: 11 | Q8: 12 | R8: 13 | S8: 14 | T8: 15 | U8: 16 | V8: 17 | W8: 18 | X8: 19 | Y8: 20 | Z8: 21 | AA8: 22 | AB8: 23 | AC8: 24 | AD8: 25 | AE8: 26 | AF8: 27 | AG8: 28 | AH8: 29 | AI8: 30 | AJ8: 31 | AK8: 32 | AL8: 33 | AM8: 34 | AN8: 35 | AO8: 36 | AP8: 37 | AQ8: 38 | AR8: 39 | AS8: 40 | AT8: 41 | AU8: 42 | AV8: 43 | AW8: 44 | AX8: 45 | AY8: 46 | AZ8: 47 | BA8: 48 | BB8: 49 | BC8: 50 | BD8: 51 | BE8: 52 | BF8: 53 | BG8: 54 | BH8: 55 | BI8: 56 | BJ8: 57 | BK8: 58 | BL8: 59 | BM8: 60 | BN8: 61 | BO8: 62 | BP8: 63 | BQ8: 64 | BR8: 65 | BS8: 66 | BT8: 67 | BU8: 68 | BV8: 69 | BW8: 70 | BX8: 71 | BY8: 72 | BZ8: 73 | CA8: 74 | CB8: 75 | CC8: 76 | CD8: 77 | CE8: 78 | CF8: 79 | CG8: 80 | CH8: 81 | CI8: 82 | CJ8: 83 | CK8: 84 | CL8: 85 | CM8: 86 | CN8: 87 | CO8: 88 | CP8: 89 | CQ8: 90+
A9: K04000001 | B9: ENGLAND AND WALES | C9: Country | D9: 31615275 | E9: 289221 | F9: 298563 | G9: 305419 | H9: 323222 | I9: 317654 | J9: 327342 | K9: 332347 | L9: 337204 | M9: 345312 | N9: 353853 | O9: 350888 | P9: 352948 | Q9: 360870 | R9: 370365 | S9: 369295 | T9: 364781 | U9: 361275 | V9: 365318 | W9: 351093 | X9: 349027 | Y9: 354068 | Z9: 353897 | AA9: 360174 | AB9: 371642 | AC9: 374941 | AD9: 383861 | AE9: 399942 | AF9: 410747 | AG9: 421466 | AH9: 414572 | AI9: 423255 | AJ9: 433744 | AK9: 435340 | AL9: 446837 | AM9: 452424 | AN9: 453194 | AO9: 450683 | AP9: 456282 | AQ9: 446010 | AR9: 439965 | AS9: 436318 | AT9: 421714 | AU9: 420873 | AV9: 415730 | AW9: 418896 | AX9: 417375 | AY9: 397991 | AZ9: 368313 | BA9: 360541 | BB9: 366457 | BC9: 372979 | BD9: 377129 | BE9: 390759 | BF9: 404999 | BG9: 421210 | BH9: 409313 | BI9: 418122 | BJ9: 415997 | BK9: 417195 | BL9: 416878 | BM9: 417115 | BN9: 410849 | BO9: 400364 | BP9: 389648 | BQ9: 372738 | BR9: 356946 | BS9: 346810 | BT9: 335351 | BU9: 321596 | BV9: 307121 | BW9: 295472 | BX9: 295143 | BY9: 287818 | BZ9: 278612 | CA9: 277483 | CB9: 279682 | CC9: 282469 | CD9: 295263 | CE9: 313846 | CF9: 235884 | CG9: 223816 | CH9: 216448 | CI9: 195001 | CJ9: 168737 | CK9: 145146 | CL9: 143481 | CM9: 134857 | CN9: 123237 | CO9: 108474 | CP9: 94627 | CQ9: 383411
A10: E92000001 | B10: ENGLAND | C10: Country | D10: 29994357 | E10: 276234 | F10: 284858 | G10: 291509 | H10: 308395 | I10: 303139 | J10: 311868 | K10: 316599 | L10: 320699 | M10: 328455 | N10: 336239 | O10: 333587 | P10: 335524 | Q10: 342883 | R10: 351781 | S10: 350748 | T10: 346309 | U10: 343282 | V10: 346825 | W10: 334181 | X10: 332286 | Y10: 336352 | Z10: 336703 | AA10: 342320 | AB10: 353011 | AC10: 356999 | AD10: 365910 | AE10: 381353 | AF10: 391744 | AG10: 401742 | AH10: 395474 | AI10: 403462 | AJ10: 413322 | AK10: 414986 | AL10: 425463 | AM10: 430591 | AN10: 431973 | AO10: 429302 | AP10: 434456 | AQ10: 424685 | AR10: 419219 | AS10: 415444 | AT10: 402074 | AU10: 400830 | AV10: 395972 | AW10: 399068 | AX10: 397574 | AY10: 379343 | AZ10: 350842 | BA10: 343592 | BB10: 348981 | BC10: 354908 | BD10: 358289 | BE10: 370636 | BF10: 383846 | BG10: 398589 | BH10: 387562 | BI10: 395257 | BJ10: 393395 | BK10: 394181 | BL10: 393846 | BM10: 393575 | BN10: 387364 | BO10: 377360 | BP10: 367381 | BQ10: 351163 | BR10: 336095 | BS10: 326432 | BT10: 315470 | BU10: 302592 | BV10: 288884 | BW10: 278000 | BX10: 277345 | BY10: 270214 | BZ10: 262058 | CA10: 260760 | CB10: 262912 | CC10: 265761 | CD10: 277792 | CE10: 295681 | CF10: 222204 | CG10: 210630 | CH10: 204004 | CI10: 183636 | CJ10: 158547 | CK10: 136333 | CL10: 135454 | CM10: 127426 | CN10: 116344 | CO10: 102338 | CP10: 89369 | CQ10: 362536
A11: E12000001 | B11: NORTH EAST | C11: Region | D11: 1408032 | E11: 11960 | F11: 12496 | G11: 12746 | H11: 13433 | I11: 13322 | J11: 13600 | K11: 14143 | L11: 14311 | M11: 14970 | N11: 15122 | O11: 14933 | P11: 15134 | Q11: 15502 | R11: 15838 | S11: 15870 | T11: 15677 | U11: 15380 | V11: 16002 | W11: 15781 | X11: 18426 | Y11: 18475 | Z11: 18103 | AA11: 17240 | AB11: 15873 | AC11: 15233 | AD11: 14946 | AE11: 15498 | AF11: 16312 | AG11: 17317 | AH11: 16949 | AI11: 17494 | AJ11: 18054 | AK11: 18165 | AL11: 19065 | AM11: 18887 | AN11: 18726 | AO11: 18660 | AP11: 19189 | AQ11: 18862 | AR11: 18762 | AS11: 18524 | AT11: 17649 | AU11: 17401 | AV11: 17242 | AW11: 17436 | AX11: 17339 | AY11: 16585 | AZ11: 14888 | BA11: 14310 | BB11: 15326 | BC11: 15277 | BD11: 15868 | BE11: 16707 | BF11: 18078 | BG11: 19172 | BH11: 18294 | BI11: 18619 | BJ11: 19134 | BK11: 19468 | BL11: 19799 | BM11: 19925 | BN11: 19844 | BO11: 19800 | BP11: 19533 | BQ11: 18637 | BR11: 18069 | BS11: 18091 | BT11: 17594 | BU11: 16778 | BV11: 16017 | BW11: 15257 | BX11: 14979 | BY11: 14691 | BZ11: 14031 | CA11: 13853 | CB11: 13918 | CC11: 13877 | CD11: 14489 | CE11: 15211 | CF11: 11098 | CG11: 10388 | CH11: 9730 | CI11: 8589 | CJ11: 7590 | CK11: 6857 | CL11: 6900 | CM11: 6285 | CN11: 5925 | CO11: 5255 | CP11: 4331 | CQ11: 16918
A12: E06000047 | B12: County Durham | C12: Unitary Authority | D12: 276304 | E12: 2131 | F12: 2366 | G12: 2264 | H12: 2372 | I12: 2296 | J12: 2471 | K12: 2463 | L12: 2639 | M12: 2724 | N12: 2824 | O12: 2840 | P12: 2870 | Q12: 2900 | R12: 2924 | S12: 2989 | T12: 3028 | U12: 2878 | V12: 3087 | W12: 3195 | X12: 4600 | Y12: 4659 | Z12: 4301 | AA12: 4041 | AB12: 3173 | AC12: 2738 | AD12: 2686 | AE12: 2766 | AF12: 2985 | AG12: 3090 | AH12: 3057 | AI12: 3141 | AJ12: 3209 | AK12: 3266 | AL12: 3394 | AM12: 3456 | AN12: 3513 | AO12: 3502 | AP12: 3494 | AQ12: 3384 | AR12: 3453 | AS12: 3366 | AT12: 3191 | AU12: 3280 | AV12: 3302 | AW12: 3303 | AX12: 3318 | AY12: 3263 | AZ12: 2913 | BA12: 2833 | BB12: 2910 | BC12: 3018 | BD12: 3166 | BE12: 3491 | BF12: 3757 | BG12: 3984 | BH12: 3755 | BI12: 3982 | BJ12: 4087 | BK12: 4035 | BL12: 4146 | BM12: 4182 | BN12: 4159 | BO12: 3939 | BP12: 3935 | BQ12: 3785 | BR12: 3597 | BS12: 3674 | BT12: 3491 | BU12: 3330 | BV12: 3242 | BW12: 3088 | BX12: 3052 | BY12: 2989 | BZ12: 2828 | CA12: 2821 | CB12: 2839 | CC12: 2893 | CD12: 2961 | CE12: 3035 | CF12: 2259 | CG12: 2238 | CH12: 2096 | CI12: 1757 | CJ12: 1527 | CK12: 1431 | CL12: 1336 | CM12: 1219 | CN12: 1130 | CO12: 1069 | CP12: 898 | CQ12: 3235
A13: E06000005 | B13: Darlington | C13: Unitary Authority | D13: 57896 | E13: 525 | F13: 545 | G13: 539 | H13: 573 | I13: 568 | J13: 626 | K13: 585 | L13: 631 | M13: 604 | N13: 626 | O13: 630 | P13: 655 | Q13: 661 | R13: 695 | S13: 674 | T13: 676 | U13: 694 | V13: 716 | W13: 661 | X13: 416 | Y13: 365 | Z13: 396 | AA13: 479 | AB13: 516 | AC13: 546 | AD13: 640 | AE13: 725 | AF13: 756 | AG13: 750 | AH13: 783 | AI13: 724 | AJ13: 728 | AK13: 800 | AL13: 743 | AM13: 847 | AN13: 750 | AO13: 829 | AP13: 836 | AQ13: 752 | AR13: 765 | AS13: 721 | AT13: 730 | AU13: 759 | AV13: 750 | AW13: 759 | AX13: 719 | AY13: 688 | AZ13: 662 | BA13: 614 | BB13: 684 | BC13: 652 | BD13: 735 | BE13: 729 | BF13: 782 | BG13: 837 | BH13: 763 | BI13: 766 | BJ13: 789 | BK13: 792 | BL13: 837 | BM13: 816 | BN13: 828 | BO13: 801 | BP13: 775 | BQ13: 766 | BR13: 716 | BS13: 713 | BT13: 713 | BU13: 666 | BV13: 642 | BW13: 575 | BX13: 574 | BY13: 590 | BZ13: 575 | CA13: 590 | CB13: 552 | CC13: 561 | CD13: 581 | CE13: 685 | CF13: 503 | CG13: 447 | CH13: 404 | CI13: 338 | CJ13: 300 | CK13: 313 | CL13: 319 | CM13: 297 | CN13: 269 | CO13: 228 | CP13: 191 | CQ13: 770
A14: E06000001 | B14: Hartlepool | C14: Unitary Authority | D14: 50911 | E14: 504 | F14: 467 | G14: 483 | H14: 494 | I14: 535 | J14: 557 | K14: 576 | L14: 526 | M14: 591 | N14: 597 | O14: 577 | P14: 598 | Q14: 583 | R14: 630 | S14: 618 | T14: 634 | U14: 614 | V14: 642 | W14: 557 | X14: 500 | Y14: 522 | Z14: 548 | AA14: 434 | AB14: 475 | AC14: 610 | AD14: 580 | AE14: 666 | AF14: 566 | AG14: 652 | AH14: 602 | AI14: 634 | AJ14: 695 | AK14: 654 | AL14: 740 | AM14: 676 | AN14: 682 | AO14: 686 | AP14: 745 | AQ14: 733 | AR14: 693 | AS14: 665 | AT14: 651 | AU14: 603 | AV14: 628 | AW14: 606 | AX14: 565 | AY14: 564 | AZ14: 576 | BA14: 530 | BB14: 530 | BC14: 504 | BD14: 560 | BE14: 597 | BF14: 632 | BG14: 709 | BH14: 678 | BI14: 695 | BJ14: 733 | BK14: 751 | BL14: 770 | BM14: 719 | BN14: 729 | BO14: 765 | BP14: 767 | BQ14: 714 | BR14: 600 | BS14: 680 | BT14: 568 | BU14: 572 | BV14: 545 | BW14: 545 | BX14: 461 | BY14: 518 | BZ14: 506 | CA14: 443 | CB14: 509 | CC14: 521 | CD14: 498 | CE14: 476 | CF14: 348 | CG14: 331 | CH14: 309 | CI14: 263 | CJ14: 282 | CK14: 216 | CL14: 245 | CM14: 202 | CN14: 234 | CO14: 190 | CP14: 129 | CQ14: 603
A15: E06000002 | B15: Middlesbrough | C15: Unitary Authority | D15: 76586 | E15: 906 | F15: 922 | G15: 929 | H15: 902 | I15: 904 | J15: 881 | K15: 861 | L15: 923 | M15: 1018 | N15: 893 | O15: 960 | P15: 940 | Q15: 1002 | R15: 1007 | S15: 1028 | T15: 963 | U15: 858 | V15: 923 | W15: 907 | X15: 865 | Y15: 864 | Z15: 958 | AA15: 875 | AB15: 953 | AC15: 972 | AD15: 950 | AE15: 911 | AF15: 1177 | AG15: 1184 | AH15: 1128 | AI15: 1151 | AJ15: 1237 | AK15: 1180 | AL15: 1190 | AM15: 1106 | AN15: 1070 | AO15: 1139 | AP15: 1114 | AQ15: 1142 | AR15: 1141 | AS15: 1115 | AT15: 1060 | AU15: 970 | AV15: 907 | AW15: 959 | AX15: 911 | AY15: 880 | AZ15: 728 | BA15: 694 | BB15: 764 | BC15: 749 | BD15: 752 | BE15: 791 | BF15: 858 | BG15: 891 | BH15: 870 | BI15: 852 | BJ15: 926 | BK15: 894 | BL15: 908 | BM15: 907 | BN15: 951 | BO15: 941 | BP15: 939 | BQ15: 909 | BR15: 858 | BS15: 878 | BT15: 864 | BU15: 850 | BV15: 786 | BW15: 757 | BX15: 690 | BY15: 660 | BZ15: 627 | CA15: 623 | CB15: 599 | CC15: 592 | CD15: 591 | CE15: 632 | CF15: 471 | CG15: 430 | CH15: 390 | CI15: 366 | CJ15: 356 | CK15: 300 | CL15: 306 | CM15: 278 | CN15: 272 | CO15: 227 | CP15: 192 | CQ15: 831
A16: E06000057 | B16: Northumberland | C16: Unitary Authority | D16: 170834 | E16: 1201 | F16: 1313 | G16: 1275 | H16: 1348 | I16: 1431 | J16: 1447 | K16: 1555 | L16: 1602 | M16: 1703 | N16: 1667 | O16: 1658 | P16: 1699 | Q16: 1735 | R16: 1835 | S16: 1751 | T16: 1754 | U16: 1720 | V16: 1779 | W16: 1596 | X16: 1279 | Y16: 1090 | Z16: 1022 | AA16: 1301 | AB16: 1365 | AC16: 1427 | AD16: 1500 | AE16: 1551 | AF16: 1660 | AG16: 1578 | AH16: 1627 | AI16: 1763 | AJ16: 1801 | AK16: 1865 | AL16: 1975 | AM16: 1954 | AN16: 1998 | AO16: 1943 | AP16: 2030 | AQ16: 1979 | AR16: 1926 | AS16: 2084 | AT16: 1943 | AU16: 1876 | AV16: 2014 | AW16: 1951 | AX16: 2136 | AY16: 1969 | AZ16: 1760 | BA16: 1764 | BB16: 1922 | BC16: 1966 | BD16: 1969 | BE16: 2163 | BF16: 2426 | BG16: 2543 | BH16: 2408 | BI16: 2521 | BJ16: 2561 | BK16: 2671 | BL16: 2792 | BM16: 2912 | BN16: 2846 | BO16: 2905 | BP16: 2842 | BQ16: 2726 | BR16: 2783 | BS16: 2673 | BT16: 2604 | BU16: 2553 | BV16: 2445 | BW16: 2310 | BX16: 2234 | BY16: 2214 | BZ16: 2179 | CA16: 2135 | CB16: 2202 | CC16: 2121 | CD16: 2376 | CE16: 2410 | CF16: 1757 | CG16: 1642 | CH16: 1514 | CI16: 1419 | CJ16: 1155 | CK16: 1025 | CL16: 1016 | CM16: 899 | CN16: 838 | CO16: 795 | CP16: 663 | CQ16: 2499
A17: E06000003 | B17: Redcar and Cleveland | C17: Unitary Authority | D17: 71800 | E17: 562 | F17: 560 | G17: 678 | H17: 731 | I17: 646 | J17: 713 | K17: 765 | L17: 732 | M17: 769 | N17: 743 | O17: 795 | P17: 776 | Q17: 830 | R17: 840 | S17: 874 | T17: 787 | U17: 790 | V17: 799 | W17: 749 | X17: 646 | Y17: 531 | Z17: 542 | AA17: 547 | AB17: 623 | AC17: 696 | AD17: 692 | AE17: 683 | AF17: 663 | AG17: 721 | AH17: 718 | AI17: 799 | AJ17: 823 | AK17: 833 | AL17: 928 | AM17: 924 | AN17: 904 | AO17: 878 | AP17: 868 | AQ17: 879 | AR17: 898 | AS17: 918 | AT17: 811 | AU17: 803 | AV17: 852 | AW17: 846 | AX17: 876 | AY17: 791 | AZ17: 742 | BA17: 686 | BB17: 766 | BC17: 719 | BD17: 824 | BE17: 871 | BF17: 933 | BG17: 1064 | BH17: 1061 | BI17: 1033 | BJ17: 1055 | BK17: 1173 | BL17: 1192 | BM17: 1186 | BN17: 1055 | BO17: 1117 | BP17: 1141 | BQ17: 996 | BR17: 993 | BS17: 1017 | BT17: 1001 | BU17: 911 | BV17: 861 | BW17: 819 | BX17: 895 | BY17: 900 | BZ17: 794 | CA17: 789 | CB17: 820 | CC17: 837 | CD17: 830 | CE17: 937 | CF17: 716 | CG17: 615 | CH17: 608 | CI17: 488 | CJ17: 498 | CK17: 397 | CL17: 437 | CM17: 394 | CN17: 331 | CO17: 293 | CP17: 259 | CQ17: 914
A18: E06000004 | B18: Stockton-on-Tees | C18: Unitary Authority | D18: 104461 | E18: 935 | F18: 1040 | G18: 1027 | H18: 1108 | I18: 1125 | J18: 1145 | K18: 1169 | L18: 1142 | M18: 1261 | N18: 1231 | O18: 1234 | P18: 1223 | Q18: 1323 | R18: 1350 | S18: 1363 | T18: 1303 | U18: 1363 | V18: 1365 | W18: 1263 | X18: 902 | Y18: 728 | Z18: 785 | AA18: 847 | AB18: 793 | AC18: 900 | AD18: 1022 | AE18: 1129 | AF18: 1093 | AG18: 1368 | AH18: 1294 | AI18: 1280 | AJ18: 1451 | AK18: 1370 | AL18: 1590 | AM18: 1482 | AN18: 1488 | AO18: 1428 | AP18: 1584 | AQ18: 1506 | AR18: 1518 | AS18: 1548 | AT18: 1465 | AU18: 1431 | AV18: 1316 | AW18: 1405 | AX18: 1332 | AY18: 1299 | AZ18: 1160 | BA18: 1104 | BB18: 1191 | BC18: 1181 | BD18: 1260 | BE18: 1176 | BF18: 1325 | BG18: 1366 | BH18: 1467 | BI18: 1356 | BJ18: 1364 | BK18: 1442 | BL18: 1433 | BM18: 1370 | BN18: 1470 | BO18: 1462 | BP18: 1468 | BQ18: 1339 | BR18: 1369 | BS18: 1303 | BT18: 1287 | BU18: 1223 | BV18: 1125 | BW18: 1088 | BX18: 1103 | BY18: 990 | BZ18: 1004 | CA18: 1033 | CB18: 932 | CC18: 935 | CD18: 1031 | CE18: 1057 | CF18: 749 | CG18: 664 | CH18: 662 | CI18: 601 | CJ18: 568 | CK18: 491 | CL18: 498 | CM18: 436 | CN18: 374 | CO18: 338 | CP18: 253 | CQ18: 1089
A19: E11000007 | B19: Tyne and Wear (Met County) | C19: Metropolitan County | D19: 599240 | E19: 5196 | F19: 5283 | G19: 5551 | H19: 5905 | I19: 5817 | J19: 5760 | K19: 6169 | L19: 6116 | M19: 6300 | N19: 6541 | O19: 6239 | P19: 6373 | Q19: 6468 | R19: 6557 | S19: 6573 | T19: 6532 | U19: 6463 | V19: 6691 | W19: 6853 | X19: 9218 | Y19: 9716 | Z19: 9551 | AA19: 8716 | AB19: 7975 | AC19: 7344 | AD19: 6876 | AE19: 7067 | AF19: 7412 | AG19: 7974 | AH19: 7740 | AI19: 8002 | AJ19: 8110 | AK19: 8197 | AL19: 8505 | AM19: 8442 | AN19: 8321 | AO19: 8255 | AP19: 8518 | AQ19: 8487 | AR19: 8368 | AS19: 8107 | AT19: 7798 | AU19: 7679 | AV19: 7473 | AW19: 7607 | AX19: 7482 | AY19: 7131 | AZ19: 6347 | BA19: 6085 | BB19: 6559 | BC19: 6488 | BD19: 6602 | BE19: 6889 | BF19: 7365 | BG19: 7778 | BH19: 7292 | BI19: 7414 | BJ19: 7619 | BK19: 7710 | BL19: 7721 | BM19: 7833 | BN19: 7806 | BO19: 7870 | BP19: 7666 | BQ19: 7402 | BR19: 7153 | BS19: 7153 | BT19: 7066 | BU19: 6673 | BV19: 6371 | BW19: 6075 | BX19: 5970 | BY19: 5830 | BZ19: 5518 | CA19: 5419 | CB19: 5465 | CC19: 5417 | CD19: 5621 | CE19: 5979 | CF19: 4295 | CG19: 4021 | CH19: 3747 | CI19: 3357 | CJ19: 2904 | CK19: 2684 | CL19: 2743 | CM19: 2560 | CN19: 2477 | CO19: 2115 | CP19: 1746 | CQ19: 6977
A20: E08000037 | B20: Gateshead | C20: Metropolitan District | D20: 102297 | E20: 921 | F20: 891 | G20: 901 | H20: 1080 | I20: 1029 | J20: 982 | K20: 1107 | L20: 1047 | M20: 1137 | N20: 1095 | O20: 1141 | P20: 1127 | Q20: 1152 | R20: 1166 | S20: 1221 | T20: 1135 | U20: 1194 | V20: 1243 | W20: 1260 | X20: 1081 | Y20: 926 | Z20: 822 | AA20: 887 | AB20: 977 | AC20: 1106 | AD20: 1095 | AE20: 1240 | AF20: 1309 | AG20: 1385 | AH20: 1300 | AI20: 1487 | AJ20: 1433 | AK20: 1376 | AL20: 1475 | AM20: 1405 | AN20: 1439 | AO20: 1407 | AP20: 1391 | AQ20: 1377 | AR20: 1432 | AS20: 1338 | AT20: 1341 | AU20: 1345 | AV20: 1219 | AW20: 1327 | AX20: 1344 | AY20: 1238 | AZ20: 1119 | BA20: 1060 | BB20: 1144 | BC20: 1129 | BD20: 1166 | BE20: 1238 | BF20: 1359 | BG20: 1382 | BH20: 1321 | BI20: 1381 | BJ20: 1342 | BK20: 1452 | BL20: 1436 | BM20: 1417 | BN20: 1355 | BO20: 1430 | BP20: 1339 | BQ20: 1292 | BR20: 1242 | BS20: 1225 | BT20: 1250 | BU20: 1174 | BV20: 1054 | BW20: 1047 | BX20: 1015 | BY20: 1001 | BZ20: 995 | CA20: 937 | CB20: 999 | CC20: 1022 | CD20: 1056 | CE20: 1087 | CF20: 762 | CG20: 785 | CH20: 705 | CI20: 618 | CJ20: 570 | CK20: 502 | CL20: 502 | CM20: 530 | CN20: 466 | CO20: 386 | CP20: 308 | CQ20: 1366
... A365: W06000022 | B365: Newport | C365: Unitary Authority | D365: 85034 | E365: 904 | F365: 962 | G365: 980 | H365: 1031 | I365: 945 | J365: 1024 | K365: 1044 | L365: 1036 | M365: 1093 | N365: 1105 | O365: 1061 | P365: 1035 | Q365: 1019 | R365: 1013 | S365: 1092 | T365: 1134 | U365: 1033 | V365: 1013 | W365: 874 | X365: 625 | Y365: 629 | Z365: 602 | AA365: 721 | AB365: 853 | AC365: 891 | AD365: 986 | AE365: 1079 | AF365: 1154 | AG365: 1188 | AH365: 1184 | AI365: 1295 | AJ365: 1243 | AK365: 1335 | AL365: 1445 | AM365: 1523 | AN365: 1410 | AO365: 1287 | AP365: 1462 | AQ365: 1360 | AR365: 1317 | AS365: 1301 | AT365: 1266 | AU365: 1108 | AV365: 1195 | AW365: 1124 | AX365: 1095 | AY365: 1006 | AZ365: 946 | BA365: 980 | BB365: 956 | BC365: 877 | BD365: 948 | BE365: 1018 | BF365: 997 | BG365: 1107 | BH365: 1000 | BI365: 1069 | BJ365: 1149 | BK365: 1086 | BL365: 1118 | BM365: 1101 | BN365: 1082 | BO365: 1027 | BP365: 1050 | BQ365: 903 | BR365: 927 | BS365: 890 | BT365: 832 | BU365: 777 | BV365: 726 | BW365: 693 | BX365: 771 | BY365: 669 | BZ365: 641 | CA365: 602 | CB365: 688 | CC365: 696 | CD365: 695 | CE365: 733 | CF365: 540 | CG365: 583 | CH365: 471 | CI365: 457 | CJ365: 470 | CK365: 395 | CL365: 352 | CM365: 329 | CN365: 284 | CO365: 268 | CP365: 218 | CQ365: 831

Sheet MYE2 - Males
A1: MYE2: Males by single year of age and sex for local authorities in England and Wales, mid-2025
A2: This worksheet contains one table. Freeze panes are turned on.
A3: To turn off freeze panes select the 'View' ribbon then 'Freeze Panes' then 'Unfreeze Panes' or use [Alt W, F]
A4: Please choose from the links presented in the cells below to e-mail us your opinion on this table:
A5: This met my needs, please produce it next year
A6: I need something slightly different (please specify)
A7: This is not what I need at all (please specify)
A8: Code | B8: Name | C8: Geography | D8: All ages | E8: 0 | F8: 1 | G8: 2 | H8: 3 | I8: 4 | J8: 5 | K8: 6 | L8: 7 | M8: 8 | N8: 9 | O8: 10 | P8: 11 | Q8: 12 | R8: 13 | S8: 14 | T8: 15 | U8: 16 | V8: 17 | W8: 18 | X8: 19 | Y8: 20 | Z8: 21 | AA8: 22 | AB8: 23 | AC8: 24 | AD8: 25 | AE8: 26 | AF8: 27 | AG8: 28 | AH8: 29 | AI8: 30 | AJ8: 31 | AK8: 32 | AL8: 33 | AM8: 34 | AN8: 35 | AO8: 36 | AP8: 37 | AQ8: 38 | AR8: 39 | AS8: 40 | AT8: 41 | AU8: 42 | AV8: 43 | AW8: 44 | AX8: 45 | AY8: 46 | AZ8: 47 | BA8: 48 | BB8: 49 | BC8: 50 | BD8: 51 | BE8: 52 | BF8: 53 | BG8: 54 | BH8: 55 | BI8: 56 | BJ8: 57 | BK8: 58 | BL8: 59 | BM8: 60 | BN8: 61 | BO8: 62 | BP8: 63 | BQ8: 64 | BR8: 65 | BS8: 66 | BT8: 67 | BU8: 68 | BV8: 69 | BW8: 70 | BX8: 71 | BY8: 72 | BZ8: 73 | CA8: 74 | CB8: 75 | CC8: 76 | CD8: 77 | CE8: 78 | CF8: 79 | CG8: 80 | CH8: 81 | CI8: 82 | CJ8: 83 | CK8: 84 | CL8: 85 | CM8: 86 | CN8: 87 | CO8: 88 | CP8: 89 | CQ8: 90+
